Workbook

Sheet NIVELADAS
B2: AUSETU
B3: SEMANA | C3: NECESSIDADE | D3: CAPACIDADE ÚTIL | E3: CARGA | F3: CAPACIDADE LIVRE | G3: UNIDADE
B4: 51.2025 | C4: 668 | D4: 704 | E4: =C4/D4 -> 0.94886364 | F4: =D4-C4 -> 36 | G4: H
B5: Total >>> | C5: =C4 -> 668 | D5: =D4 -> 704 | E5: =E4 -> 0.94886364 | F5: =F4 -> 36 | G5: =G4 -> H
B7: CALDTU
B8: SEMANA | C8: NECESSIDADE | D8: CAPACIDADE ÚTIL | E8: CARGA | F8: CAPACIDADE LIVRE | G8: UNIDADE
B9: 51.2025 | C9: 588.4 | D9: 528 | E9: =C9/D9 -> 1.1143939 | F9: =D9-C9 -> -60.4 | G9: H
B10: Total >>> | C10: =C9 -> 588.4 | D10: =D9 -> 528 | E10: =E9 -> 1.1143939 | F10: =F9 -> -60.4 | G10: =G9 -> H
B12: MANDTU
B13: SEMANA | C13: NECESSIDADE | D13: CAPACIDADE ÚTIL | E13: CARGA | F13: CAPACIDADE LIVRE | G13: UNIDADE
B14: 51.2025 | C14: 1271.2 | D14: 1056 | E14: =C14/D14 -> 1.2037879 | F14: =D14-C14 -> -215.2 | G14: H
B15: Total >>> | C15: =C14 -> 1271.2 | D15: =D14 -> 1056 | E15: =E14 -> 1.2037879 | F15: =F14 -> -215.2 | G15: =G14 -> H
B17: TRANSFERENCIA E ESTOCAGEM | E17: UTILIDADES
B18: AUSETU | I18: AUSETU
I19: TOTAL | J19: =SUM(J20:J21) -> 680.4 | K19: =E4 -> 0.94886364
I20: TE | J20: ='AUSETU T.E'!H1 -> 397.2 | K20: =J20*K19/J19 -> 0.55392216
I21: UT | J21: ='AUSETU UT'!H1 -> 283.2 | K21: =J21*K19/J19 -> 0.39494148
B29: CALDTU | I29: CALDTU
I30: TOTAL | J30: =SUM(J31:J32) -> 605.8 | K30: =E9 -> 1.1143939
I31: TE | J31: ='CALDTU T.E'!H1 -> 141.8 | K31: =J31*K30/J30 -> 0.26084691
I32: UT | J32: ='CALDTU UT'!H1 -> 464 | K32: =J32*K30/J30 -> 0.85354703
B40: MANDTU | I40: MANDTU
I41: TOTAL | J41: =SUM(J42:J43) -> 1340 | K41: =E14 -> 1.2037879
I42: TE | J42: ='MANDTU T.E'!H1 -> 398 | K42: =K41*J42/J41 -> 0.35754297
I43: UT | J43: ='MANDTU UT'!H1 -> 942 | K43: =K41*J43/J41 -> 0.84624491
N44: 100 | O44: =SUM(J47+J48) -> 1.2206623
O45: =J47*N44 -> 52.241784
I46: TOTAL | O46: =J48*N44 -> 69.824447
I47: TE | J47: =SUM(K19+K31+K42)/3 -> 0.52241784 | K47: =K51 -> 0.427979
I48: UT | J48: =SUM(K21+K32+K43)/3 -> 0.69824447
I50: TOTAL
I51: TE | K51: =O45/O44/100 -> 0.427979
I52: UT | K52: =O46/O44/100 -> 0.572021

Sheet AUSETU T.E
H1: =SUM(H3:H1048576) -> 397.2
A2: Confirm | B2: Ordem | C2: Oper | D2: Subop | E2: CenTrabOp | F2: Txt. Breve operação | G2: executenta | H2: Trabalho | I2: TrbReal | J2: Duração
A3: 132037102 | B3: 2026886835 | C3: 350 | E3: AUSETU | F3: TQ-4113:Repor terra após Concretagem | G3: 4 | H3: 24 | I3: 0 | J3: 6 | K3: 14.01.2026 | L3: 0.62083333 | M3: 15.01.2026 | N3: 0.40416667 | O3: NDEL EVCO | P3: IMPR LIB PLAN | Q3: ZM01 | T3: 0 | W3: 0 | Y3: 0 | Z3: 0 | AA3: 1 | AB3: NÃO SE APLICA | AC3: 18
A4: 133844750 | B4: 2027914281 | C4: 290 | E4: AUSETU | F4: TQ-4107: Tamponar furo solo/prep solo | G4: 2 | H4: 8 | I4: 0 | J4: 4 | K4: 12.01.2026 | L4: 0.3125 | M4: 12.01.2026 | N4: 0.44583333 | O4: NDEL EVCO | P4: LIB PLAN | Q4: ZM01 | T4: 0 | W4: 0 | Y4: 0 | Z4: 0 | AA4: 1 | AB4: NÃO SE APLICA | AC4: 18
A5: 134628342 | B5: 2027914281 | C5: 580 | E5: AUSETU | F5: TQ-4107: Nivelar solo com terra | G5: 2 | H5: 12 | I5: 0 | J5: 6 | K5: 12.01.2026 | L5: 0.3125 | M5: 12.01.2026 | N5: 0.55416667 | O5: NDEL | P5: LIB PLAN | Q5: ZM01 | T5: 0 | W5: 0 | Y5: 0 | Z5: 0 | AA5: 1 | AB5: NÃO SE APLICA | AC5: 18
A6: 134628343 | B6: 2027914281 | C6: 590 | E6: AUSETU | F6: $LIMP TQ-4107: Realizar limpeza geral | G6: 2 | H6: 8 | I6: 0 | J6: 4 | K6: 12.01.2026 | L6: 0.3125 | M6: 12.01.2026 | N6: 0.44583333 | O6: NDEL | P6: LIB PLAN | Q6: ZM01 | T6: 0 | W6: 0 | Y6: 0 | Z6: 0 | AA6: 1 | AB6: NÃO SE APLICA | AC6: 18
A7: 134626869 | B7: 2028975154 | C7: 212 | D7: 10 | E7: AUSETU | F7: V-4023A: Apoio desraqueteamento | G7: 1 | H7: 4 | I7: 0 | J7: 4 | K7: 12.01.2026 | L7: 0 | M7: 12.01.2026 | N7: 0.16666667 | O7: NDEL | P7: LIB PLAN | Q7: ZM01 | T7: 0 | W7: 0 | Y7: 0 | Z7: 0 | AA7: 2 | AB7: NÃO SE APLICA | AC7: 18
A8: 121381331 | B8: 2029466654 | C8: 40 | E8: AUSETU | F8: M-A-7410_Remover MA da lagoa | G8: 2 | H8: 6 | I8: 0 | J8: 3 | K8: 12.01.2026 | L8: 0.16666667 | M8: 12.01.2026 | N8: 0.29166667 | O8: NDEL | P8: LIB PLAN | Q8: ZM01 | T8: 0 | W8: 0 | Y8: 0 | Z8: 0 | AA8: 2 | AB8: NÃO SE APLICA | AC8: 18
A9: 122279722 | B9: 2029655578 | C9: 20 | E9: AUSETU | F9: TE- CO5- Limpeza Are Pq Bomba e piso MLD | G9: 2 | H9: 16 | I9: 0 | J9: 8 | K9: 13.01.2026 | L9: 0.35416667 | M9: 13.01.2026 | N9: 0.6625 | O9: NDEL CO03 | P9: LIB PLAN | Q9: ZM01 | T9: 0 | W9: 1 | Y9: 0 | Z9: 0 | AA9: 1 | AB9: NÃO SE APLICA | AC9: 18
A10: 122279746 | B10: 2029655578 | C10: 26 | E10: AUSETU | F10: TE - CO7 - Limpeza Area e Pq Bomba | G10: 2 | H10: 16 | I10: 0 | J10: 8 | K10: 14.01.2026 | L10: 0.36916667 | M10: 14.01.2026 | N10: 0.6775 | O10: NDEL CO03 | P10: LIB PLAN | Q10: ZM01 | T10: 0 | W10: 1 | Y10: 0 | Z10: 0 | AA10: 1 | AB10: NÃO SE APLICA | AC10: 18
A11: 122279747 | B11: 2029655578 | C11: 27 | E11: AUSETU | F11: TE - Soda -organização e limpeza Pq Desc | G11: 2 | H11: 8 | I11: 0 | J11: 4 | K11: 14.01.2026 | L11: 0.6775 | M11: 15.01.2026 | N11: 0.39416667 | O11: NDEL CO03 | P11: LIB PLAN | Q11: ZM01 | T11: 0 | W11: 1 | Y11: 0 | Z11: 0 | AA11: 1 | AB11: NÃO SE APLICA | AC11: 18
A12: 122279710 | B12: 2029655578 | C12: 40 | E12: AUSETU | F12: TE - CO6 - Limpeza Area e Pq Bomba | G12: 2 | H12: 16 | I12: 0 | J12: 8 | K12: 16.01.2026 | L12: 0.3125 | M12: 16.01.2026 | N12: 0.62083333 | O12: NDEL CO03 | P12: LIB PLAN | Q12: ZM01 | R12: 2 | S12: 16.01.2026 | T12: 0 | W12: 1 | Y12: 0 | Z12: 0 | AA12: 1 | AB12: NÃO SE APLICA | AC12: 18
A13: 122279734 | B13: 2029655578 | C13: 150 | E13: AUSETU | F13: TE - CO2 - Limpeza Area e Pq Bomba | G13: 2 | H13: 16 | I13: 0 | J13: 8 | K13: 16.01.2026 | L13: 0.59416667 | M13: 19.01.2026 | N13: 0.48583333 | O13: NDEL CO03 | P13: LIB PLAN | Q13: ZM01 | T13: 0 | W13: 1 | Y13: 0 | Z13: 0 | AA13: 1 | AB13: NÃO SE APLICA | AC13: 18
A14: 133309829 | B14: 2030591598 | C14: 45 | E14: AUSETU | F14: TQ-4812:Nivelar dique conforme padrão | G14: 4 | H14: 64 | I14: 0 | J14: 16 | K14: 12.01.2026 | L14: 0.37916667 | M14: 13.01.2026 | N14: 0.57916667 | O14: NDEL CO03 | P14: LIB PLAN | Q14: ZM01 | T14: 0 | W14: 0 | Y14: 0 | Z14: 0 | AA14: 1 | AB14: NÃO SE APLICA | AC14: 18
A15: 128758191 | B15: 2030591598 | C15: 60 | E15: AUSETU | F15: TQ-4812: Anexar (PRCO) | G15: 1 | H15: 0.2 | I15: 0 | J15: 0.2 | K15: 13.01.2026 | L15: 0.57916667 | M15: 13.01.2026 | N15: 0.58583333 | O15: NDEL EVCO EXCO | P15: LIB PLAN | Q15: ZM01 | T15: 0 | W15: 0 | Y15: 0 | Z15: 0 | AA15: 1 | AB15: NÃO SE APLICA | AC15: 18
A16: 131800773 | B16: 2031021354 | C16: 30 | E16: AUSETU | F16: $LIMP PE-4901: Limp. ext. válvula globo | G16: 2 | H16: 2 | I16: 0 | J16: 1 | K16: 15.01.2026 | L16: 0.44583333 | M16: 15.01.2026 | N16: 0.47916667 | O16: NDEL CO03 | P16: LIB PLAN | Q16: ZM01 | T16: 0 | W16: 0 | Y16: 0 | Z16: 0 | AA16: 1 | AB16: NÃO SE APLICA | AC16: 18
A17: 131800780 | B17: 2031021354 | C17: 80 | E17: AUSETU | F17: $LIMP PE-4901: Realizar limpeza do local | G17: 2 | H17: 4 | I17: 0 | J17: 2 | K17: 16.01.2026 | L17: 0.41916667 | M17: 16.01.2026 | N17: 0.48583333 | O17: NDEL CO03 | P17: LIB PLAN | Q17: ZM01 | T17: 0 | W17: 0 | Y17: 0 | Z17: 0 | AA17: 1 | AB17: NÃO SE APLICA | AC17: 18
A18: 134170433 | B18: 2031025962 | C18: 20 | E18: AUSETU | F18: TW-08-Inst contenção/ realiz limpeza | G18: 2 | H18: 8 | I18: 0 | J18: 4 | K18: 12.01.2026 | L18: 0.47916667 | M18: 12.01.2026 | N18: 0.6875 | O18: NDEL | P18: LIB PLAN | Q18: ZM01 | T18: 0 | W18: 0 | Y18: 0 | Z18: 0 | AA18: 2 | AB18: NÃO SE APLICA | AC18: 18
A19: 132755779 | B19: 2031216118 | C19: 200 | E19: AUSETU | F19: TQ-4120: Recolher mangotes | G19: 8 | H19: 64 | I19: 0 | J19: 8 | K19: 12.01.2026 | L19: 0.9408912 | M19: 13.01.2026 | N19: 0.27422454 | O19: NDEL EVCO | P19: LIB PLAN | Q19: ZM01 | T19: 0 | W19: 0 | Y19: 0 | Z19: 0 | AA19: 1 | AB19: NÃO SE APLICA | AC19: 18
A20: 132755780 | B20: 2031216118 | C20: 210 | E20: AUSETU | F20: TQ-4120: Realizar limpeza dos mangotes | G20: 2 | H20: 12 | I20: 0 | J20: 6 | K20: 13.01.2026 | L20: 0.27422454 | M20: 13.01.2026 | N20: 0.52422454 | O20: NDEL CO03 EVCO | P20: LIB PLAN | Q20: ZM01 | T20: 0 | W20: 0 | Y20: 0 | Z20: 0 | AA20: 1 | AB20: NÃO SE APLICA | AC20: 18
A21: 132755784 | B21: 2031216118 | C21: 230 | E21: AUSETU | F21: TQ-4120:Transp mang/bomb/gerador | G21: 2 | H21: 4 | I21: 0 | J21: 2 | K21: 13.01.2026 | L21: 0.6908912 | M21: 13.01.2026 | N21: 0.77422454 | O21: NDEL EVCO | P21: LIB PLAN | Q21: ZM01 | T21: 0 | W21: 0 | Y21: 0 | Z21: 0 | AA21: 1 | AB21: NÃO SE APLICA | AC21: 18
A22: 132873197 | B22: 2031234202 | C22: 10 | E22: AUSETU | F22: UTDI - Limpar grades/Filtros/Rolo BP/API | G22: 2 | H22: 24 | I22: 0 | J22: 12 | K22: 12.01.2026 | L22: 0.3125 | M22: 13.01.2026 | N22: 0.3375 | O22: NDEL | P22: LIB PLAN | Q22: ZM01 | T22: 0 | W22: 1 | X22: X | Y22: 0 | Z22: 0 | AA22: 1 | AB22: NÃO SE APLICA | AC22: 18
A23: 133417461 | B23: 2031323727 | C23: 30 | E23: AUSETU | F23: UTDI /TE:Apoio carreg/desc.produtos qu. | G23: 2 | H23: 18 | I23: 0 | J23: 9 | K23: 13.01.2026 | L23: 0.34416667 | M23: 13.01.2026 | N23: 0.68583333 | O23: NDEL | P23: LIB PLAN | Q23: ZM01 | T23: 0 | W23: 1 | Y23: 0 | Z23: 0 | AA23: 1 | AB23: NÃO SE APLICA | AC23: 18
A24: 134034541 | B24: 2031412109 | C24: 20 | D24: 10 | E24: AUSETU | F24: RACE_RUA-15F:Esc Trech Sanar vaz | G24: 4 | H24: 48 | I24: 0 | J24: 12 | K24: 13.01.2026 | L24: 0.57916667 | M24: 14.01.2026 | N24: 0.60416667 | O24: NDEL | P24: LIB PLAN | Q24: ZM01 | T24: 0 | W24: 0 | Y24: 0 | Z24: 0 | AA24: 2 | AB24: REPLAN/SMS/SO-2025-141 | AC24: 14
A25: 134045389 | B25: 2031412678 | C25: 20 | E25: AUSETU | F25: $LIMP BOMBEIO B-4083: Limpar Piso/ cap | G25: 2 | H25: 6 | I25: 0 | J25: 3 | K25: 15.01.2026 | L25: 0.63916667 | M25: 16.01.2026 | N25: 0.3225 | O25: NDEL | P25: LIB PLAN | Q25: ZM01 | T25: 0 | W25: 0 | Y25: 0 | Z25: 0 | AA25: 1 | AB25: NÃO SE APLICA | AC25: 18
A26: 134565422 | B26: 2031508728 | C26: 45 | E26: AUSETU | F26: $LIMP TQ-4808: Realizar limpeza bloqueio | G26: 2 | H26: 4 | I26: 0 | J26: 2 | K26: 13.01.2026 | L26: 0.39583333 | M26: 13.01.2026 | N26: 0.47916667 | O26: NDEL CO03 | P26: LIB PLAN | Q26: ZM01 | T26: 0 | W26: 0 | Y26: 0 | Z26: 0 | AA26: 1 | AB26: NÃO SE APLICA | AC26: 18
A27: 134619164 | B27: 2031520505 | C27: 30 | E27: AUSETU | F27: B-7425-Limpeza do mangote de sucção. | G27: 2 | H27: 4 | I27: 0 | J27: 2 | K27: 12.01.2026 | L27: 0.6875 | M27: 13.01.2026 | N27: 0.35416667 | O27: NDEL | P27: LIB PLAN | Q27: ZM01 | T27: 0 | W27: 1 | X27: X | Y27: 0 | Z27: 0 | AB27: NÃO SE APLICA | AC27: 18
A28: 134619175 | B28: 2031520505 | C28: 120 | E28: AUSETU | F28: B-7425-Afogar mangote | G28: 1 | H28: 1 | I28: 0 | J28: 1 | K28: 14.01.2026 | L28: 0.37916667 | M28: 14.01.2026 | N28: 0.42083333 | O28: NDEL | P28: LIB PLAN | Q28: ZM01 | T28: 0 | W28: 1 | Y28: 0 | Z28: 0 | AB28: NÃO SE APLICA | AC28: 18

Sheet CALDTU T.E
H1: =SUM(H3:H1048576) -> 141.8
A2: Confirm | B2: Ordem | C2: Oper | D2: Subop | E2: CenTrabOp | F2: Txt. Breve operação | G2: executenta | H2: Trabalho | I2: TrbReal | J2: Duração
A3: 123166996 | B3: 2029717491 | C3: 130 | E3: CALDTU | F3: V-73101:PRCO Anexar relatório | G3: 1 | H3: 0.2 | I3: 0 | J3: 0.2 | K3: 13.01.2026 | L3: 0.40416667 | M3: 13.01.2026 | N3: 0.41083333 | O3: NDEL EVCO | P3: LIB PLAN | Q3: ZM01 | T3: 0 | W3: 0 | Y3: 0 | Z3: 0 | AA3: 1 | AB3: NÃO SE APLICA | AC3: 18
A4: 125191742 | B4: 2030059635 | C4: 340 | E4: CALDTU | F4: B-4014: Instar dreno/ sanar vazamento | G4: 2 | H4: 8 | I4: 0 | J4: 4 | K4: 12.01.2026 | L4: 0.3125 | M4: 12.01.2026 | N4: 0.47916667 | O4: NDEL EVCO | P4: JBFI LIB PLAN PWF | Q4: ZM01 | T4: 0 | W4: 0 | Y4: 0 | Z4: 0 | AA4: 2 | AB4: NÃO SE APLICA | AC4: 18
A5: 134185091 | B5: 2030059635 | C5: 380 | E5: CALDTU | F5: B-4014: Desraquetear sistemas | G5: 2 | H5: 8 | I5: 0 | J5: 4 | K5: 12.01.2026 | L5: 0.5625 | M5: 12.01.2026 | N5: 0.72916667 | O5: NDEL EVCO | P5: LIB PLAN | Q5: ZM01 | T5: 0 | W5: 0 | Y5: 0 | Z5: 0 | AA5: 2 | AB5: NÃO SE APLICA | AC5: 18
A6: 127359076 | B6: 2030402239 | C6: 25 | E6: CALDTU | F6: B-40142C-Instalar mang para liberação | G6: 2 | H6: 4 | I6: 0 | J6: 2 | K6: 12.01.2026 | L6: 0.39583333 | M6: 12.01.2026 | N6: 0.47916667 | O6: NDEL | P6: LIB PLAN | Q6: ZM01 | T6: 0 | W6: 0 | Y6: 0 | Z6: 0 | AA6: 2 | AB6: NÃO SE APLICA | AC6: 18
A7: 130521176 | B7: 2030854280 | C7: 40 | E7: CALDTU | F7: TQ-4404: Adequar dreno fundo (Encurtar) | G7: 2 | H7: 6 | I7: 0 | J7: 3 | K7: 15.01.2026 | L7: 0.35416667 | M7: 15.01.2026 | N7: 0.45416667 | O7: NDEL EVCO | P7: LIB PLAN | Q7: ZM01 | T7: 0 | W7: 0 | Y7: 0 | Z7: 0 | AA7: 1 | AB7: NÃO SE APLICA | AC7: 18
A8: 130521177 | B8: 2030854280 | C8: 50 | E8: CALDTU | F8: TQ-4404: Instalar dreno de fundo | G8: 2 | H8: 4 | I8: 0 | J8: 2 | K8: 15.01.2026 | L8: 0.45416667 | M8: 15.01.2026 | N8: 0.5625 | O8: NDEL EVCO | P8: LIB PLAN | Q8: ZM01 | T8: 0 | W8: 0 | Y8: 0 | Z8: 0 | AA8: 1 | AB8: NÃO SE APLICA | AC8: 18
A9: 130521178 | B9: 2030854280 | C9: 60 | E9: CALDTU | F9: TQ-4404: PRCO Anexar relatório | G9: 1 | H9: 0.2 | I9: 0 | J9: 0.2 | K9: 15.01.2026 | L9: 0.56583333 | M9: 15.01.2026 | N9: 0.5725 | O9: NDEL EVCO | P9: LIB PLAN | Q9: ZM01 | T9: 0 | W9: 0 | Y9: 0 | Z9: 0 | AA9: 1 | AB9: NÃO SE APLICA | AC9: 18
A10: 131800779 | B10: 2031021354 | C10: 70 | D10: 10 | E10: CALDTU | F10: PE-4901: Realizar reaperto no castelo | G10: 1 | H10: 2 | I10: 0 | J10: 2 | K10: 16.01.2026 | L10: 0.3525 | M10: 16.01.2026 | N10: 0.41916667 | O10: NDEL | P10: LIB PLAN | Q10: ZM01 | T10: 0 | W10: 0 | Y10: 0 | Z10: 0 | AA10: 1 | AB10: NÃO SE APLICA | AC10: 18
A11: 131800776 | B11: 2031021354 | C11: 35 | E11: CALDTU | F11: PE-4901: PRCO Anexar relatório válv Glob | G11: 1 | H11: 0.2 | I11: 0 | J11: 0.2 | K11: 15.01.2026 | L11: 0.5625 | M11: 15.01.2026 | N11: 0.56916667 | O11: NDEL | P11: LIB PLAN | Q11: ZM01 | T11: 0 | W11: 0 | Y11: 0 | Z11: 0 | AA11: 1 | AB11: NÃO SE APLICA | AC11: 18
A12: 134170432 | B12: 2031025962 | C12: 10 | E12: CALDTU | F12: TW-08-Raquetear linha | G12: 2 | H12: 8 | I12: 0 | J12: 4 | K12: 12.01.2026 | L12: 0.3125 | M12: 12.01.2026 | N12: 0.47916667 | O12: NDEL | P12: LIB PLAN | Q12: ZM01 | T12: 0 | W12: 0 | Y12: 0 | Z12: 0 | AA12: 2 | AB12: NÃO SE APLICA | AC12: 18
A13: 134170441 | B13: 2031025962 | C13: 80 | E13: CALDTU | F13: TW-08-Desraquetear linha | G13: 2 | H13: 8 | I13: 0 | J13: 4 | K13: 15.01.2026 | L13: 0.375 | M13: 15.01.2026 | N13: 0.58333333 | O13: NDEL | P13: LIB PLAN | Q13: ZM01 | T13: 0 | W13: 0 | Y13: 0 | Z13: 0 | AA13: 2 | AB13: NÃO SE APLICA | AC13: 18
A14: 132755777 | B14: 2031216118 | C14: 180 | E14: CALDTU | F14: TQ-4120: Desonectar/ conectar mango | G14: 2 | H14: 12 | I14: 0 | J14: 6 | K14: 12.01.2026 | L14: 0.60755787 | M14: 12.01.2026 | N14: 0.85755787 | O14: NDEL EVCO | P14: LIB PLAN | Q14: ZM01 | T14: 0 | W14: 0 | Y14: 0 | Z14: 0 | AA14: 1 | AB14: NÃO SE APLICA | AC14: 18
A15: 132755789 | B15: 2031216118 | C15: 300 | E15: CALDTU | F15: TQ-4120: PRCO: Anexar relatório | G15: 1 | H15: 0.2 | I15: 0 | J15: 0.2 | K15: 13.01.2026 | L15: 0.77422454 | M15: 13.01.2026 | N15: 0.78255787 | O15: NDEL EVCO | P15: LIB PLAN | Q15: ZM01 | T15: 0 | W15: 0 | Y15: 0 | Z15: 0 | AA15: 1 | AB15: NÃO SE APLICA | AC15: 18
A16: 132909451 | B16: 2031237722 | C16: 10 | E16: CALDTU | F16: TQ-4702: Dimensionar Placa p/ Instalação | G16: 2 | H16: 2 | I16: 0 | J16: 1 | K16: 12.01.2026 | L16: 0.44583333 | M16: 12.01.2026 | N16: 0.47916667 | O16: NDEL | P16: LIB PLAN | Q16: ZM01 | T16: 0 | W16: 0 | Y16: 0 | Z16: 0 | AA16: 1 | AB16: NÃO SE APLICA | AC16: 18
A17: 132960499 | B17: 2031237722 | C17: 30 | E17: CALDTU | F17: TQ-4702: Cortar/furar/ soldar placa | G17: 2 | H17: 4 | I17: 0 | J17: 2 | K17: 16.01.2026 | L17: 0.45416667 | M17: 16.01.2026 | N17: 0.5625 | O17: NDEL | P17: LIB PLAN | Q17: ZM01 | T17: 0 | W17: 0 | Y17: 0 | Z17: 0 | AA17: 1 | AB17: NÃO SE APLICA | AC17: 18
A18: 132909454 | B18: 2031237723 | C18: 10 | E18: CALDTU | F18: TQ-7408:Dimensionar placa p/ instalação | G18: 2 | H18: 2 | I18: 0 | J18: 1 | K18: 12.01.2026 | L18: 0.44583333 | M18: 12.01.2026 | N18: 0.47916667 | O18: NDEL | P18: LIB PLAN | Q18: ZM01 | T18: 0 | W18: 0 | Y18: 0 | Z18: 0 | AA18: 1 | AB18: NÃO SE APLICA | AC18: 18
A19: 132960530 | B19: 2031237723 | C19: 30 | E19: CALDTU | F19: TQ-7408: Cortar/furar/ soldar placa | G19: 2 | H19: 4 | I19: 0 | J19: 2 | K19: 15.01.2026 | L19: 0.4375 | M19: 15.01.2026 | N19: 0.54583333 | O19: NDEL | P19: LIB PLAN | Q19: ZM01 | T19: 0 | W19: 0 | Y19: 0 | Z19: 0 | AA19: 1 | AB19: NÃO SE APLICA | AC19: 18
A20: 132960534 | B20: 2031237723 | C20: 60 | E20: CALDTU | F20: TQ-7408: Instalar placa acesso restrito | G20: 2 | H20: 4 | I20: 0 | J20: 2 | K20: 16.01.2026 | L20: 0.42916667 | M20: 16.01.2026 | N20: 0.49583333 | O20: NDEL | P20: LIB PLAN | Q20: ZM01 | T20: 0 | W20: 0 | Y20: 0 | Z20: 0 | AA20: 1 | AB20: NÃO SE APLICA | AC20: 18
A21: 132960535 | B21: 2031237723 | C21: 70 | E21: CALDTU | F21: TQ-7408: PRCO Anexar relatório | G21: 1 | H21: 0.2 | I21: 0 | J21: 0.2 | K21: 16.01.2026 | L21: 0.49583333 | M21: 16.01.2026 | N21: 0.54416667 | O21: NDEL | P21: LIB PLAN | Q21: ZM01 | T21: 0 | W21: 0 | Y21: 0 | Z21: 0 | AA21: 1 | AB21: NÃO SE APLICA | AC21: 18
A22: 133125989 | B22: 2031265724 | C22: 10 | E22: CALDTU | F22: BIRUTA-REPLAN-09: Cortar tubo (haste) | G22: 2 | H22: 2 | I22: 0 | J22: 1 | K22: 12.01.2026 | L22: 0.72083333 | M22: 13.01.2026 | N22: 0.3375 | O22: NDEL EVCO | P22: LIB PLAN | Q22: ZM01 | T22: 0 | W22: 0 | Y22: 0 | Z22: 0 | AA22: 1 | AB22: NÃO SE APLICA | AC22: 14
... A36: 134567981 | B36: 2031508728 | C36: 70 | E36: CALDTU | F36: $MANG TQ-4808: Remover mangueiras | G36: 2 | H36: 4 | I36: 0 | J36: 2 | K36: 13.01.2026 | L36: 0.60416667 | M36: 13.01.2026 | N36: 0.6875 | O36: NDEL CA01 | P36: LIB PLAN | Q36: ZM01 | T36: 0 | W36: 0 | Y36: 0 | Z36: 0 | AA36: 1 | AB36: NÃO SE APLICA | AC36: 18
A37: 134619160 | B37: 2031520505 | C37: 10 | E37: CALDTU | F37: B-7425-Remover mangote de sucção p/limpe | G37: 2 | H37: 6 | I37: 0 | J37: 3 | K37: 12.01.2026 | L37: 0.39583333 | M37: 12.01.2026 | N37: 0.5625 | O37: NDEL | P37: LIB PLAN | Q37: ZM01 | T37: 0 | W37: 1 | X37: X | Y37: 0 | Z37: 0 | AB37: NÃO SE APLICA | AC37: 18
A38: 134619165 | B38: 2031520505 | C38: 40 | E38: CALDTU | F38: B-7425-Intalar mangote de sucção após a | G38: 2 | H38: 6 | I38: 0 | J38: 3 | K38: 13.01.2026 | L38: 0.35416667 | M38: 13.01.2026 | N38: 0.47916667 | O38: NDEL | P38: LIB PLAN | Q38: ZM01 | T38: 0 | W38: 1 | X38: X | Y38: 0 | Z38: 0 | AB38: NÃO SE APLICA | AC38: 18
A39: 134617984 | B39: 2031520505 | C39: 140 | E39: CALDTU | F39: B-7425- PRCO Anexar relatório | G39: 1 | H39: 0.2 | I39: 0 | J39: 0.2 | K39: 14.01.2026 | L39: 0.4625 | M39: 14.01.2026 | N39: 0.47083333 | O39: NDEL | P39: LIB PLAN | Q39: ZM01 | T39: 0 | W39: 0 | Y39: 0 | Z39: 0 | AB39: NÃO SE APLICA | AC39: 18
A40: 134619920 | B40: 2031520830 | C40: 10 | E40: CALDTU | F40: B-7455:Remover mangote de sucção p/limpe | G40: 2 | H40: 6 | I40: 0 | J40: 3 | K40: 12.01.2026 | L40: 0.39583333 | M40: 12.01.2026 | N40: 0.5625 | O40: NDEL | P40: LIB PLAN | Q40: ZM01 | T40: 0 | W40: 1 | X40: X | Y40: 0 | Z40: 0 | AB40: NÃO SE APLICA | AC40: 18
A41: 134619944 | B41: 2031520833 | C41: 10 | E41: CALDTU | F41: B-7454:Remover mangote de sucção p/limpe | G41: 2 | H41: 2 | I41: 0 | J41: 1 | K41: 12.01.2026 | L41: 0.39583333 | M41: 12.01.2026 | N41: 0.4375 | O41: NDEL | P41: LIB PLAN | Q41: ZM01 | T41: 0 | W41: 1 | X41: X | Y41: 0 | Z41: 0 | AB41: NÃO SE APLICA | AC41: 18

Sheet MANDTU T.E
H1: =SUM(H3:H1048576) -> 398
A2: Confirm | B2: Ordem | C2: Oper | D2: Subop | E2: CenTrabOp | F2: Txt. Breve operação | G2: executenta | H2: Trabalho | I2: TrbReal | J2: Duração
A3: 105945436 | B3: 2026777600 | C3: 10 | E3: MANDTU | F3: PCV-49013_Montar pau de carga | G3: 4 | H3: 16 | I3: 0 | J3: 4 | K3: 15.01.2026 | L3: 0.7125 | M3: 16.01.2026 | N3: 0.4625 | O3: NDEL CO01 | P3: LIB PLAN | Q3: ZM01 | T3: 0 | W3: 0 | Y3: 0 | Z3: 0 | AA3: 2 | AB3: NÃO SE APLICA | AC3: 18
A4: 133844745 | B4: 2027914281 | C4: 275 | E4: MANDTU | F4: $MAND TQ-4107: Montar andaime acesso | G4: 4 | H4: 16 | I4: 0 | J4: 4 | K4: 12.01.2026 | L4: 0.44583333 | M4: 12.01.2026 | N4: 0.62083333 | O4: NDEL EVCO | P4: LIB PLAN | Q4: ZM01 | T4: 0 | W4: 0 | Y4: 0 | Z4: 0 | AA4: 1 | AB4: NÃO SE APLICA | AC4: 18
A5: 133844756 | B5: 2027914281 | C5: 300 | E5: MANDTU | F5: TQ-4107: Montar barraca Confinamento | G5: 4 | H5: 16 | I5: 0 | J5: 4 | K5: 12.01.2026 | L5: 0.44583333 | M5: 12.01.2026 | N5: 0.62083333 | O5: NDEL EVCO | P5: LIB PLAN | Q5: ZM01 | T5: 0 | W5: 0 | Y5: 0 | Z5: 0 | AA5: 1 | AB5: NÃO SE APLICA | AC5: 18
A6: 116655735 | B6: 2028286018 | C6: 290 | E6: MANDTU | F6: MCV-4671_D.A de acesso ao atuador | G6: 4 | H6: 8 | I6: 0 | J6: 2 | K6: 12.01.2026 | L6: 0.6875 | M6: 13.01.2026 | N6: 0.3375 | O6: NDEL CO01 | P6: LIB PLAN | Q6: ZM01 | T6: 0 | W6: 0 | Y6: 0 | Z6: 0 | AA6: 1 | AB6: NÃO SE APLICA | AC6: 18
A7: 117101929 | B7: 2028493669 | C7: 15 | E7: MANDTU | F7: MCV-4928_M.A plat/pau-de-carga(escada) | G7: 4 | H7: 16 | I7: 0 | J7: 4 | K7: 12.01.2026 | L7: 0.3125 | M7: 12.01.2026 | N7: 0.44583333 | O7: NDEL | P7: LIB PLAN | Q7: ZM01 | T7: 0 | W7: 0 | Y7: 0 | Z7: 0 | AA7: 1 | AB7: NÃO SE APLICA | AC7: 18
A8: 132993858 | B8: 2028602605 | C8: 35 | E8: MANDTU | F8: VA-4910: Desmontar andaime acesso teto | G8: 4 | H8: 8 | I8: 0 | J8: 2 | K8: 12.01.2026 | L8: 0.62083333 | M8: 12.01.2026 | N8: 0.6875 | O8: NDEL EVCO | P8: LIB PLAN | Q8: ZM01 | T8: 0 | W8: 0 | Y8: 0 | Z8: 0 | AA8: 1 | AB8: NÃO SE APLICA | AC8: 18
A9: 121381330 | B9: 2029466654 | C9: 30 | E9: MANDTU | F9: M-A-7410_M.A.suporte para aerador | G9: 4 | H9: 16 | I9: 0 | J9: 4 | K9: 12.01.2026 | L9: 0 | M9: 12.01.2026 | N9: 0.16666667 | O9: NDEL | P9: LIB PLAN | Q9: ZM01 | T9: 0 | W9: 0 | Y9: 0 | Z9: 0 | AA9: 2 | AB9: NÃO SE APLICA | AC9: 18
A10: 123166995 | B10: 2029717491 | C10: 120 | E10: MANDTU | F10: V-73101: Desmontar barraca confinamento | G10: 4 | H10: 8 | I10: 0 | J10: 2 | K10: 13.01.2026 | L10: 0.3375 | M10: 13.01.2026 | N10: 0.40416667 | O10: NDEL CO01 EVCO | P10: LIB PLAN | Q10: ZM01 | T10: 0 | W10: 0 | Y10: 0 | Z10: 0 | AA10: 1 | AB10: NÃO SE APLICA | AC10: 18
A11: 128146277 | B11: 2030381392 | C11: 10 | E11: MANDTU | F11: VE-40035 M.A. p/ passagem de cabo | G11: 4 | H11: 24 | I11: 0 | J11: 6 | K11: 14.01.2026 | L11: 0.6675 | M11: 15.01.2026 | N11: 0.45083333 | O11: NDEL CO01 | P11: LIB PLAN | Q11: ZM01 | T11: 0 | W11: 0 | Y11: 0 | Z11: 0 | AA11: 1 | AB11: NÃO SE APLICA | AC11: 18
A12: 127232888 | B12: 2030402239 | C12: 10 | E12: MANDTU | F12: B-40142B-M.A bancada acesso vaso acumula | G12: 4 | H12: 8 | I12: 0 | J12: 2 | K12: 12.01.2026 | L12: 0.3125 | M12: 12.01.2026 | N12: 0.39583333 | O12: NDEL CO01 | P12: LIB PLAN | Q12: ZM01 | T12: 0 | W12: 0 | Y12: 0 | Z12: 0 | AA12: 2 | AB12: NÃO SE APLICA | AC12: 18
A13: 127359074 | B13: 2030402239 | C13: 15 | E13: MANDTU | F13: B-40142C-M.A. barraca/escora de linha | G13: 4 | H13: 8 | I13: 0 | J13: 2 | K13: 12.01.2026 | L13: 0.39583333 | M13: 12.01.2026 | N13: 0.47916667 | O13: NDEL CO01 | P13: LIB PLAN | Q13: ZM01 | T13: 0 | W13: 0 | Y13: 0 | Z13: 0 | AA13: 2 | AB13: NÃO SE APLICA | AC13: 18
A14: 127365061 | B14: 2030402573 | C14: 310 | E14: MANDTU | F14: B-5106A-D.A. após manutenção | G14: 4 | H14: 8 | I14: 0 | J14: 2 | K14: 14.01.2026 | L14: 0.43583333 | M14: 14.01.2026 | N14: 0.54416667 | O14: NDEL | P14: LIB PLAN | Q14: ZM01 | T14: 0 | W14: 0 | Y14: 0 | Z14: 0 | AA14: 2 | AB14: NÃO SE APLICA | AC14: 18
... A26: 134567982 | B26: 2031508728 | C26: 80 | E26: MANDTU | F26: $MAND TQ-4808: Desmontar andaime acesso | G26: 4 | H26: 8 | I26: 0 | J26: 2 | K26: 13.01.2026 | L26: 0.6875 | M26: 14.01.2026 | N26: 0.35416667 | O26: NDEL CO01 | P26: LIB PLAN | Q26: ZM01 | T26: 0 | W26: 0 | Y26: 0 | Z26: 0 | AA26: 1 | AB26: NÃO SE APLICA | AC26: 18
A27: 134619174 | B27: 2031520505 | C27: 5 | E27: MANDTU | F27: B-7425-Montar andaime de acesso | G27: 4 | H27: 8 | I27: 0 | J27: 2 | K27: 12.01.2026 | L27: 0.3125 | M27: 12.01.2026 | N27: 0.39583333 | O27: NDEL | P27: LIB PLAN | Q27: ZM01 | T27: 0 | W27: 1 | Y27: 0 | Z27: 0 | AB27: NÃO SE APLICA | AC27: 18
A28: 134619179 | B28: 2031520505 | C28: 130 | E28: MANDTU | F28: B-7425-Desmontar andaime de acesso | G28: 4 | H28: 4 | I28: 0 | J28: 1 | K28: 14.01.2026 | L28: 0.42083333 | M28: 14.01.2026 | N28: 0.4625 | O28: NDEL | P28: LIB PLAN | Q28: ZM01 | T28: 0 | W28: 1 | Y28: 0 | Z28: 0 | AB28: NÃO SE APLICA | AC28: 18
A29: 134619934 | B29: 2031520830 | C29: 5 | E29: MANDTU | F29: B-7455: Montar andaime de acesso | G29: 4 | H29: 8 | I29: 0 | J29: 2 | K29: 12.01.2026 | L29: 0.3125 | M29: 12.01.2026 | N29: 0.39583333 | O29: NDEL | P29: LIB PLAN | Q29: ZM01 | T29: 0 | W29: 1 | Y29: 0 | Z29: 0 | AB29: NÃO SE APLICA | AC29: 18
A30: 134619958 | B30: 2031520833 | C30: 5 | E30: MANDTU | F30: B-7454: Montar andaime de acesso | G30: 4 | H30: 8 | I30: 0 | J30: 2 | K30: 12.01.2026 | L30: 0.3125 | M30: 12.01.2026 | N30: 0.39583333 | O30: NDEL | P30: LIB PLAN | Q30: ZM01 | T30: 0 | W30: 1 | Y30: 0 | Z30: 0 | AB30: NÃO SE APLICA | AC30: 18

Sheet AUSETU UT
H1: =SUM(H3:H1048576) -> 283.2
A2: Confirm | B2: Ordem | C2: Oper | D2: Subop | E2: CenTrabOp | F2: Txt. Breve operação | G2: executenta | H2: Trabalho | I2: TrbReal | J2: Duração
A3: 129596782 | B3: 2029484416 | C3: 220 | E3: AUSETU | F3: S-6302A:Emitir relatório PRCO | G3: 1 | H3: 0.2 | I3: 0 | J3: 0.2 | K3: 12.01.2026 | L3: 0 | M3: 12.01.2026 | N3: 0.0083333333 | O3: NDEL EVCO EXCO | P3: LIB PLAN | Q3: ZM01 | T3: 0 | W3: 0 | Y3: 0 | Z3: 0 | AA3: 2 | AB3: NÃO SE APLICA | AC3: 19
A4: 134282091 | B4: 2029780007 | C4: 2505 | E4: AUSETU | F4: U-620(UTDI):Acompanhame.transferên.DIA | G4: 1 | H4: 44 | I4: 0 | J4: 44 | K4: 12.01.2026 | L4: 0.3125 | M4: 15.01.2026 | N4: 0.69583333 | O4: NDEL | P4: LIB PLAN | Q4: ZM01 | T4: 0 | W4: 0 | Y4: 0 | Z4: 0 | AB4: NÃO SE APLICA | AC4: 19
A5: 125755036 | B5: 2029900061 | C5: 1010 | E5: AUSETU | F5: V-6207:Remover sistema de exaustão | G5: 2 | H5: 4 | I5: 0 | J5: 2 | K5: 12.01.2026 | L5: 0 | M5: 12.01.2026 | N5: 0.083333333 | O5: NDEL | P5: IMPR LIB PLAN | Q5: ZM01 | T5: 0 | W5: 0 | Y5: 0 | Z5: 0 | AC5: 19
A6: 127519871 | B6: 2030329233 | C6: 20 | D6: 10 | E6: AUSETU | F6: V-6303B:Ap.remover isol.térm.para raquet | G6: 1 | H6: 2 | I6: 0 | J6: 2 | K6: 12.01.2026 | L6: 0 | M6: 12.01.2026 | N6: 0.083333333 | O6: NDEL | P6: LIB PLAN | Q6: ZM01 | T6: 0 | W6: 0 | Y6: 0 | Z6: 0 | AA6: 2 | AB6: NÃO SE APLICA | AC6: 19
A7: 127519878 | B7: 2030329233 | C7: 70 | D7: 10 | E7: AUSETU | F7: V-6303B:Monitorar entrada e saida de pes | G7: 1 | H7: 2 | I7: 0 | J7: 2 | K7: 12.01.2026 | L7: 0 | M7: 12.01.2026 | N7: 0.083333333 | O7: NDEL | P7: LIB PLAN | Q7: ZM01 | T7: 0 | W7: 0 | Y7: 0 | Z7: 0 | AA7: 2 | AB7: NÃO SE APLICA | AC7: 19
A8: 127519880 | B8: 2030329233 | C8: 80 | D8: 10 | E8: AUSETU | F8: V-6303B:Monitorar entrada e saida de pes | G8: 1 | H8: 4 | I8: 0 | J8: 4 | K8: 12.01.2026 | L8: 0 | M8: 12.01.2026 | N8: 0.16666667 | O8: NDEL | P8: LIB PLAN | Q8: ZM01 | T8: 0 | W8: 0 | Y8: 0 | Z8: 0 | AA8: 2 | AB8: NÃO SE APLICA | AC8: 19
A9: 127519882 | B9: 2030329233 | C9: 90 | D9: 10 | E9: AUSETU | F9: V-6303B:Monitorar entrada e saida de pes | G9: 1 | H9: 4 | I9: 0 | J9: 4 | K9: 12.01.2026 | L9: 0.083333333 | M9: 12.01.2026 | N9: 0.25 | O9: NDEL | P9: LIB PLAN | Q9: ZM01 | T9: 0 | W9: 0 | Y9: 0 | Z9: 0 | AA9: 2 | AB9: NÃO SE APLICA | AC9: 19
A10: 127519887 | B10: 2030329233 | C10: 500 | D10: 10 | E10: AUSETU | F10: V-6303B:Monitorar entrada e saida de pes | G10: 1 | H10: 3 | I10: 0 | J10: 3 | K10: 12.01.2026 | L10: 0.25 | M10: 12.01.2026 | N10: 0.375 | O10: NDEL | P10: LIB PLAN | Q10: ZM01 | T10: 0 | W10: 0 | Y10: 0 | Z10: 0 | AA10: 2 | AB10: NÃO SE APLICA | AC10: 19
A11: 127519890 | B11: 2030329233 | C11: 520 | D11: 10 | E11: AUSETU | F11: V-6303B:Monitorar entrada e saida de pes | G11: 1 | H11: 6 | I11: 0 | J11: 6 | K11: 12.01.2026 | L11: 0 | M11: 12.01.2026 | N11: 0.25 | O11: NDEL | P11: LIB PLAN | Q11: ZM01 | T11: 0 | W11: 0 | Y11: 0 | Z11: 0 | AA11: 2 | AB11: NÃO SE APLICA | AC11: 19
A12: 127519894 | B12: 2030329233 | C12: 550 | D12: 10 | E12: AUSETU | F12: V-6303B:Ap.refazer isol.térm.após desraq | G12: 1 | H12: 4 | I12: 0 | J12: 4 | K12: 12.01.2026 | L12: 0 | M12: 12.01.2026 | N12: 0.16666667 | O12: NDEL | P12: LIB PLAN | Q12: ZM01 | T12: 0 | W12: 0 | Y12: 0 | Z12: 0 | AA12: 2 | AB12: NÃO SE APLICA | AC12: 19
A13: 127519885 | B13: 2030329233 | C13: 100 | D13: 20 | E13: AUSETU | F13: V-6303B:Monitorar entrada e saida de pes | G13: 1 | H13: 4 | I13: 0 | J13: 4 | K13: 12.01.2026 | L13: 0 | M13: 12.01.2026 | N13: 0.16666667 | O13: NDEL | P13: LIB PLAN | Q13: ZM01 | T13: 0 | W13: 0 | Y13: 0 | Z13: 0 | AA13: 2 | AB13: NÃO SE APLICA | AC13: 19
A14: 127519874 | B14: 2030329233 | C14: 50 | E14: AUSETU | F14: V-6303B:Instalar sistema de exaustão | G14: 2 | H14: 4 | I14: 0 | J14: 2 | K14: 12.01.2026 | L14: 0 | M14: 12.01.2026 | N14: 0.083333333 | O14: NDEL | P14: LIB PLAN | Q14: ZM01 | T14: 0 | W14: 0 | Y14: 0 | Z14: 0 | AA14: 2 | AB14: NÃO SE APLICA | AC14: 19
A15: 127519879 | B15: 2030329233 | C15: 80 | E15: AUSETU | F15: V-6303B:Execuatar limpeza interna para i | G15: 2 | H15: 8 | I15: 0 | J15: 4 | K15: 12.01.2026 | L15: 0 | M15: 12.01.2026 | N15: 0.16666667 | O15: NDEL | P15: LIB PLAN | Q15: ZM01 | T15: 0 | W15: 0 | Y15: 0 | Z15: 0 | AA15: 2 | AB15: NÃO SE APLICA | AC15: 19
A16: 127519889 | B16: 2030329233 | C16: 520 | E16: AUSETU | F16: V-6303B: Realizar limpeza interna | G16: 2 | H16: 12 | I16: 0 | J16: 6 | K16: 12.01.2026 | L16: 0 | M16: 12.01.2026 | N16: 0.25 | O16: NDEL | P16: LIB PLAN | Q16: ZM01 | T16: 0 | W16: 0 | Y16: 0 | Z16: 0 | AA16: 2 | AB16: NÃO SE APLICA | AC16: 19
A17: 134195306 | B17: 2030707957 | C17: 230 | E17: AUSETU | F17: ETA:Apoio transf.prod.químico 3ªsemana | G17: 2 | H17: 4 | I17: 0 | J17: 2 | K17: 12.01.2026 | L17: 0.3125 | M17: 12.01.2026 | N17: 0.39583333 | O17: NDEL | P17: LIB PLAN | Q17: ZM01 | T17: 0 | W17: 0 | Y17: 0 | Z17: 0 | AC17: 19
A18: 134624688 | B18: 2030707957 | C18: 300 | E18: AUSETU | F18: ETA:Apoio transf.prod.químico 3ªsemana | G18: 2 | H18: 4 | I18: 0 | J18: 2 | K18: 12.01.2026 | L18: 0.3125 | M18: 12.01.2026 | N18: 0.39583333 | O18: NDEL | P18: LIB PLAN | Q18: ZM01 | T18: 0 | W18: 0 | Y18: 0 | Z18: 0 | AC18: 19
A19: 132685318 | B19: 2031202862 | C19: 30 | E19: AUSETU | F19: P-B-61101A-Limpar Permutador | G19: 2 | H19: 4 | I19: 0 | J19: 2 | K19: 12.01.2026 | L19: 0.62083333 | M19: 12.01.2026 | N19: 0.6875 | O19: NDEL CO03 | P19: LIB PLAN | Q19: ZM01 | T19: 0 | W19: 1 | X19: X | Y19: 0 | Z19: 0 | AC19: 19
A20: 133107771 | B20: 2031240660 | C20: 410 | D20: 10 | E20: AUSETU | F20: P-6302B Observador espaço confinado | G20: 1 | H20: 4 | I20: 0 | J20: 4 | K20: 12.01.2026 | L20: 0 | M20: 12.01.2026 | N20: 0.16666667 | O20: NDEL | P20: LIB PLAN | Q20: ZM01 | T20: 0 | W20: 0 | Y20: 0 | Z20: 0 | AA20: 2 | AB20: NÃO SE APLICA | AC20: 19
A21: 133107775 | B21: 2031240660 | C21: 450 | D21: 10 | E21: AUSETU | F21: P-6302B Observador espaço confinado | G21: 1 | H21: 2 | I21: 0 | J21: 2 | K21: 12.01.2026 | L21: 0 | M21: 12.01.2026 | N21: 0.083333333 | O21: NDEL | P21: LIB PLAN | Q21: ZM01 | T21: 0 | W21: 0 | Y21: 0 | Z21: 0 | AA21: 2 | AB21: NÃO SE APLICA | AC21: 19
A22: 133107768 | B22: 2031240660 | C22: 390 | E22: AUSETU | F22: P-6302B Montar Estrutura Espaço Confinad | G22: 2 | H22: 4 | I22: 0 | J22: 2 | K22: 12.01.2026 | L22: 0 | M22: 12.01.2026 | N22: 0.083333333 | O22: NDEL | P22: LIB PLAN | Q22: ZM01 | T22: 0 | W22: 0 | Y22: 0 | Z22: 0 | AA22: 2 | AB22: NÃO SE APLICA | AC22: 19
A23: 133107770 | B23: 2031240660 | C23: 410 | E23: AUSETU | F23: P-6302B Realizar Limpeza Interna Casco | G23: 2 | H23: 8 | I23: 0 | J23: 4 | K23: 12.01.2026 | L23: 0 | M23: 12.01.2026 | N23: 0.16666667 | O23: NDEL | P23: LIB PLAN | Q23: ZM01 | T23: 0 | W23: 0 | Y23: 0 | Z23: 0 | AA23: 2 | AB23: NÃO SE APLICA | AC23: 19
A24: 133107773 | B24: 2031240660 | C24: 440 | E24: AUSETU | F24: P-6302B Observador espaço confinado | G24: 1 | H24: 6 | I24: 0 | J24: 6 | K24: 12.01.2026 | L24: 0 | M24: 12.01.2026 | N24: 0.25 | O24: NDEL | P24: LIB PLAN | Q24: ZM01 | T24: 0 | W24: 0 | Y24: 0 | Z24: 0 | AA24: 2 | AB24: NÃO SE APLICA | AC24: 19
A25: 133107776 | B25: 2031240660 | C25: 470 | E25: AUSETU | F25: P-6302B Realizar Limpeza Intern Carretel | G25: 2 | H25: 4 | I25: 0 | J25: 2 | K25: 12.01.2026 | L25: 0 | M25: 12.01.2026 | N25: 0.083333333 | O25: NDEL | P25: LIB PLAN | Q25: ZM01 | T25: 0 | W25: 0 | Y25: 0 | Z25: 0 | AA25: 2 | AB25: NÃO SE APLICA | AC25: 19
A26: 133107777 | B26: 2031240660 | C26: 480 | E26: AUSETU | F26: P-6302B Desmon Estrutura Espaço Confinad | G26: 2 | H26: 4 | I26: 0 | J26: 2 | K26: 12.01.2026 | L26: 0 | M26: 12.01.2026 | N26: 0.083333333 | O26: NDEL | P26: LIB PLAN | Q26: ZM01 | T26: 0 | W26: 0 | Y26: 0 | Z26: 0 | AA26: 2 | AB26: NÃO SE APLICA | AC26: 19
A27: 133107778 | B27: 2031240660 | C27: 490 | E27: AUSETU | F27: P-6302B Desmontar Painel Elétrico | G27: 2 | H27: 4 | I27: 0 | J27: 2 | K27: 12.01.2026 | L27: 0 | M27: 12.01.2026 | N27: 0.083333333 | O27: NDEL | P27: LIB PLAN | Q27: ZM01 | T27: 0 | W27: 0 | Y27: 0 | Z27: 0 | AA27: 2 | AB27: NÃO SE APLICA | AC27: 19
A28: 133425167 | B28: 2031265635 | C28: 160 | D28: 10 | E28: AUSETU | F28: V-6204E:Vigia esp.conf.Recompor internos | G28: 1 | H28: 6 | I28: 0 | J28: 6 | K28: 12.01.2026 | L28: 0.16666667 | M28: 12.01.2026 | N28: 0.41666667 | O28: NDEL | P28: IMPR LIB PLAN | Q28: ZM01 | T28: 0 | W28: 0 | Y28: 0 | Z28: 0 | AB28: NÃO SE APLICA | AC28: 19
A29: 133425170 | B29: 2031265635 | C29: 180 | E29: AUSETU | F29: V-6204E:Remover iluminação/exaustão | G29: 2 | H29: 8 | I29: 0 | J29: 4 | K29: 12.01.2026 | L29: 0 | M29: 12.01.2026 | N29: 0.16666667 | O29: NDEL | P29: IMPR LIB PLAN | Q29: ZM01 | T29: 0 | W29: 0 | Y29: 0 | Z29: 0 | AB29: NÃO SE APLICA | AC29: 19
A30: 133425173 | B30: 2031265635 | C30: 280 | E30: AUSETU | F30: V-6204E:Repor resina | G30: 2 | H30: 24 | I30: 0 | J30: 12 | K30: 12.01.2026 | L30: 0 | M30: 12.01.2026 | N30: 0.5 | O30: NDEL | P30: IMPR LIB PLAN | Q30: ZM01 | T30: 0 | W30: 0 | Y30: 0 | Z30: 0 | AB30: NÃO SE APLICA | AC30: 19
A31: 133425174 | B31: 2031265635 | C31: 290 | E31: AUSETU | F31: V-6204E:Remover ejetor | G31: 2 | H31: 6 | I31: 0 | J31: 3 | K31: 12.01.2026 | L31: 0 | M31: 12.01.2026 | N31: 0.125 | O31: NDEL | P31: IMPR LIB PLAN | Q31: ZM01 | T31: 0 | W31: 0 | Y31: 0 | Z31: 0 | AB31: NÃO SE APLICA | AC31: 19
A32: 133559710 | B32: 2031348916 | C32: 60 | E32: AUSETU | F32: CAFOR:Limp.de piso de área 2ª semana | G32: 2 | H32: 16 | I32: 0 | J32: 8 | K32: 12.01.2026 | L32: 0.44583333 | M32: 13.01.2026 | N32: 0.3375 | O32: NDEL | P32: LIB PLAN | Q32: ZM01 | T32: 0 | W32: 1 | Y32: 0 | Z32: 0 | AA32: 1 | AB32: NÃO SE APLICA | AC32: 19
A33: 133559711 | B33: 2031348916 | C33: 70 | E33: AUSETU | F33: CAFOR:Limp.de piso GV's-2201/501 2ª sem. | G33: 2 | H33: 16 | I33: 0 | J33: 8 | K33: 13.01.2026 | L33: 0.3375 | M33: 13.01.2026 | N33: 0.64583333 | O33: NDEL | P33: LIB PLAN | Q33: ZM01 | T33: 0 | W33: 1 | Y33: 0 | Z33: 0 | AA33: 1 | AB33: NÃO SE APLICA | AC33: 19
A34: 133559738 | B34: 2031348916 | C34: 85 | E34: AUSETU | F34: TG-6301ABC_Limpeza casulos 2° semana | G34: 2 | H34: 18 | I34: 0 | J34: 9 | K34: 14.01.2026 | L34: 0.6375 | M34: 15.01.2026 | N34: 0.5625 | O34: NDEL | P34: LIB PLAN | Q34: ZM01 | T34: 0 | W34: 1 | Y34: 0 | Z34: 0 | AA34: 1 | AB34: NÃO SE APLICA | AC34: 19
A35: 133559713 | B35: 2031348916 | C35: 90 | E35: AUSETU | F35: CAFOR:Limp.de piso de área 2ª semana | G35: 2 | H35: 32 | I35: 0 | J35: 16 | K35: 15.01.2026 | L35: 0.5625 | M35: 19.01.2026 | N35: 0.34583333 | O35: NDEL | P35: LIB PLAN | Q35: ZM01 | T35: 0 | W35: 1 | Y35: 0 | Z35: 0 | AA35: 1 | AB35: NÃO SE APLICA | AC35: 19
A36: 134440805 | B36: 2031482284 | C36: 30 | E36: AUSETU | F36: C-6312B-Lavar base na área | G36: 2 | H36: 8 | I36: 0 | J36: 4 | K36: 13.01.2026 | L36: 0.63333333 | M36: 14.01.2026 | N36: 0.38333333 | O36: NDEL | P36: LIB PLAN | Q36: ZM01 | T36: 0 | W36: 0 | Y36: 0 | Z36: 0 | AA36: 1 | AB36: NÃO SE APLICA | AC36: 19

Sheet CALDTU UT
H1: =SUM(H3:H1048576) -> 464
A2: Confirm | B2: Ordem | C2: Oper | D2: Subop | E2: CenTrabOp | F2: Txt. Breve operação | G2: executenta | H2: Trabalho | I2: TrbReal | J2: Duração
A3: 114052335 | B3: 2028265715 | C3: 130 | E3: CALDTU | F3: R-VE-6151H-Remover cabo de linha de vida | G3: 2 | H3: 4 | I3: 0 | J3: 2 | K3: 12.01.2026 | L3: 0.72045139 | M3: 13.01.2026 | N3: 0.38711806 | O3: NDEL | P3: LIB PLAN | Q3: ZM01 | T3: 0 | W3: 0 | Y3: 0 | Z3: 0 | AB3: NÃO SE APLICA | AC3: 19
A4: 134596248 | B4: 2028265715 | C4: 142 | E4: CALDTU | F4: R-VE-6151H Virar figura 8 | G4: 2 | H4: 8 | I4: 0 | J4: 4 | K4: 13.01.2026 | L4: 0.67878472 | M4: 14.01.2026 | N4: 0.42878472 | O4: NDEL | P4: LIB PLAN | Q4: ZM01 | T4: 0 | W4: 0 | Y4: 0 | Z4: 0 | AB4: NÃO SE APLICA | AC4: 19
A5: 117749497 | B5: 2028854655 | C5: 150 | E5: CALDTU | F5: V-6341A:ANEXAR RELATÓRIO (PRCO) | G5: 1 | H5: 0.2 | I5: 0 | J5: 0.2 | K5: 12.01.2026 | L5: 0.3125 | M5: 12.01.2026 | N5: 0.31916667 | O5: NDEL EVCO EXCO | P5: LIB PLAN | Q5: ZM01 | T5: 0 | W5: 0 | Y5: 0 | Z5: 0 | AA5: 2 | AB5: NÃO SE APLICA | AC5: 19
A6: 122426472 | B6: 2029456516 | C6: 20 | E6: CALDTU | F6: PN-4105_Recuperar telhado | G6: 2 | H6: 54 | I6: 0 | J6: 27 | K6: 13.01.2026 | L6: 0.62083333 | M6: 16.01.2026 | N6: 0.35416667 | O6: NDEL | P6: LIB PLAN | Q6: ZM01 | T6: 0 | W6: 0 | Y6: 0 | Z6: 0 | AA6: 1 | AB6: NÃO SE APLICA | AC6: 19
A7: 121226621 | B7: 2029456516 | C7: 40 | E7: CALDTU | F7: PN-4105_Tirar dimensional telhado | G7: 2 | H7: 4 | I7: 0 | J7: 2 | K7: 16.01.2026 | L7: 0.3875 | M7: 16.01.2026 | N7: 0.45416667 | O7: NDEL | P7: LIB PLAN | Q7: ZM01 | T7: 0 | W7: 0 | Y7: 0 | Z7: 0 | AA7: 1 | AB7: NÃO SE APLICA | AC7: 19
A8: 129596777 | B8: 2029484416 | C8: 170 | E8: CALDTU | F8: S-6302A:Fechar BV superior após limpeza | G8: 2 | H8: 4 | I8: 0 | J8: 2 | K8: 12.01.2026 | L8: 0 | M8: 12.01.2026 | N8: 0.083333333 | O8: NDEL EVCO | P8: JBFI LIB PLAN PWF | Q8: ZM01 | T8: 0 | W8: 0 | Y8: 0 | Z8: 0 | AA8: 2 | AB8: NÃO SE APLICA | AC8: 19
A9: 129596778 | B9: 2029484416 | C9: 180 | E9: CALDTU | F9: S-6302A:Realizar o desraquet secador | G9: 2 | H9: 8 | I9: 0 | J9: 4 | K9: 12.01.2026 | L9: 0 | M9: 12.01.2026 | N9: 0.16666667 | O9: NDEL EVCO | P9: LIB PLAN | Q9: ZM01 | T9: 0 | W9: 0 | Y9: 0 | Z9: 0 | AA9: 2 | AB9: NÃO SE APLICA | AC9: 19
A10: 121735287 | B10: 2029508737 | C10: 130 | E10: CALDTU | F10: PI-63556:Emitir relatório PRCO | G10: 1 | H10: 0.2 | I10: 0 | J10: 0.2 | K10: 12.01.2026 | L10: 0.6375 | M10: 12.01.2026 | N10: 0.64416667 | O10: NDEL | P10: LIB PLAN | Q10: ZM01 | T10: 0 | W10: 0 | Y10: 0 | Z10: 0 | AA10: 2 | AB10: NÃO SE APLICA | AC10: 19
A11: 125755037 | B11: 2029900061 | C11: 1020 | E11: CALDTU | F11: V-6207:Fechar BV do vaso após inspeção i | G11: 2 | H11: 4 | I11: 0 | J11: 2 | K11: 12.01.2026 | L11: 0 | M11: 12.01.2026 | N11: 0.083333333 | O11: NDEL | P11: IMPR LIB PLAN | Q11: ZM01 | T11: 0 | W11: 0 | Y11: 0 | Z11: 0 | AC11: 19
A12: 125755038 | B12: 2029900061 | C12: 1030 | E12: CALDTU | F12: V-6207:Remover raquetes das linhas do va | G12: 2 | H12: 8 | I12: 0 | J12: 4 | K12: 12.01.2026 | L12: 0 | M12: 12.01.2026 | N12: 0.16666667 | O12: NDEL | P12: IMPR LIB PLAN | Q12: ZM01 | T12: 0 | W12: 0 | Y12: 0 | Z12: 0 | AC12: 19
A13: 127910766 | B13: 2029900061 | C13: 1050 | E13: CALDTU | F13: V-6207:Emitir Relatório (PRCO) | G13: 1 | H13: 0.2 | I13: 0 | J13: 0.2 | K13: 12.01.2026 | L13: 0 | M13: 12.01.2026 | N13: 0.0083333333 | O13: NDEL | P13: IMPR LIB PLAN | Q13: ZM01 | T13: 0 | W13: 0 | Y13: 0 | Z13: 0 | AC13: 19
A14: 126468979 | B14: 2030272491 | C14: 40 | E14: CALDTU | F14: BL-6201A:Subst.Cilindro de Cloro 4ª sem. | G14: 2 | H14: 8 | I14: 0 | J14: 4 | K14: 12.01.2026 | L14: 0.3125 | M14: 12.01.2026 | N14: 0.44583333 | O14: NDEL | P14: LIB PLAN | Q14: ZM01 | T14: 0 | W14: 0 | Y14: 0 | Z14: 0 | AC14: 19
A15: 127122540 | B15: 2030377954 | C15: 370 | E15: CALDTU | F15: TQ-6216:Insta.Bloqueio/carretel/suportes | G15: 2 | H15: 16 | I15: 0 | J15: 8 | K15: 12.01.2026 | L15: 0 | M15: 12.01.2026 | N15: 0.33333333 | O15: NDEL EVCO | P15: LIB PLAN | Q15: ZM01 | T15: 0 | W15: 0 | Y15: 0 | Z15: 0 | AB15: NÃO SE APLICA | AC15: 19
A16: 134617901 | B16: 2030377954 | C16: 405 | E16: CALDTU | F16: TQ-6216:Inst. vent na linha sucção fase2 | G16: 2 | H16: 10 | I16: 0 | J16: 5 | K16: 12.01.2026 | L16: 0 | M16: 12.01.2026 | N16: 0.20833333 | O16: NDEL | P16: LIB PLAN | Q16: ZM01 | T16: 0 | W16: 0 | Y16: 0 | Z16: 0 | AB16: NÃO SE APLICA | AC16: 19
A17: 127122543 | B17: 2030377954 | C17: 410 | E17: CALDTU | F17: TQ-6216:PAC Emitir relatório PRCO | G17: 1 | H17: 0.2 | I17: 0 | J17: 0.2 | K17: 12.01.2026 | L17: 0 | M17: 12.01.2026 | N17: 0.0083333333 | O17: NDEL EVCO EXCO | P17: LIB PLAN | Q17: ZM01 | T17: 0 | W17: 0 | Y17: 0 | Z17: 0 | AB17: NÃO SE APLICA | AC17: 19
A18: 128533768 | B18: 2030382934 | C18: 200 | E18: CALDTU | F18: XV-62304_Remover XV Antiga | G18: 2 | H18: 6 | I18: 0 | J18: 3 | K18: 12.01.2026 | L18: 0.39583333 | M18: 12.01.2026 | N18: 0.49583333 | O18: NDEL | P18: LIB PLAN | Q18: ZM01 | T18: 0 | W18: 0 | Y18: 0 | Z18: 0 | AB18: NÃO SE APLICA | AC18: 19
A19: 128533769 | B19: 2030382934 | C19: 210 | E19: CALDTU | F19: XV-62304_Instalar XV Nova | G19: 2 | H19: 6 | I19: 0 | J19: 3 | K19: 12.01.2026 | L19: 0.49583333 | M19: 12.01.2026 | N19: 0.6375 | O19: NDEL | P19: LIB PLAN | Q19: ZM01 | T19: 0 | W19: 0 | Y19: 0 | Z19: 0 | AB19: NÃO SE APLICA | AC19: 19
A20: 127507340 | B20: 2030452771 | C20: 20 | E20: CALDTU | F20: B-6302D:Subst.bloq.do PI-63062D | G20: 2 | H20: 8 | I20: 0 | J20: 4 | K20: 12.01.2026 | L20: 0.5625 | M20: 12.01.2026 | N20: 0.72916667 | O20: NDEL EVCO | P20: LIB PLAN | Q20: ZM01 | T20: 0 | W20: 0 | Y20: 0 | Z20: 0 | AA20: 2 | AB20: NÃO SE APLICA | AC20: 19
A21: 127507341 | B21: 2030452771 | C21: 30 | E21: CALDTU | F21: B-6302D:Adequar linha do PI-63062D | G21: 2 | H21: 8 | I21: 0 | J21: 4 | K21: 13.01.2026 | L21: 0.3125 | M21: 13.01.2026 | N21: 0.47916667 | O21: NDEL EVCO | P21: LIB PLAN | Q21: ZM01 | T21: 0 | W21: 0 | Y21: 0 | Z21: 0 | AA21: 2 | AB21: NÃO SE APLICA | AC21: 19
A22: 127507343 | B22: 2030452771 | C22: 50 | E22: CALDTU | F22: B-6302D:PI-63062D Emitir relat.PRCO | G22: 1 | H22: 0.2 | I22: 0 | J22: 0.2 | K22: 14.01.2026 | L22: 0.3125 | M22: 14.01.2026 | N22: 0.32083333 | O22: NDEL EVCO | P22: LIB PLAN | Q22: ZM01 | T22: 0 | W22: 0 | Y22: 0 | Z22: 0 | AA22: 2 | AB22: NÃO SE APLICA | AC22: 19
A23: 134040312 | B23: 2030707957 | C23: 190 | E23: CALDTU | F23: ETA:Apoio transf.prod.químico 4ªsemana | G23: 2 | H23: 2 | I23: 0 | J23: 1 | K23: 12.01.2026 | L23: 0.3125 | M23: 12.01.2026 | N23: 0.35416667 | O23: NDEL | P23: LIB PLAN | Q23: ZM01 | T23: 0 | W23: 0 | Y23: 0 | Z23: 0 | AC23: 19
A24: 134195305 | B24: 2030707957 | C24: 220 | E24: CALDTU | F24: ETA:Apoio transf.prod.químico4ªsemana | G24: 2 | H24: 2 | I24: 0 | J24: 1 | K24: 12.01.2026 | L24: 0.3125 | M24: 12.01.2026 | N24: 0.35416667 | O24: NDEL | P24: LIB PLAN | Q24: ZM01 | T24: 0 | W24: 0 | Y24: 0 | Z24: 0 | AC24: 19
A25: 134624687 | B25: 2030707957 | C25: 290 | E25: CALDTU | F25: ETA:Apoio transf.prod.químico3ªsemana | G25: 2 | H25: 2 | I25: 0 | J25: 1 | K25: 12.01.2026 | L25: 0.3125 | M25: 12.01.2026 | N25: 0.35416667 | O25: NDEL | P25: LIB PLAN | Q25: ZM01 | T25: 0 | W25: 0 | Y25: 0 | Z25: 0 | AC25: 19
A26: 132714193 | B26: 2030740098 | C26: 230 | D26: 10 | E26: CALDTU | F26: XV-62245_Instalar novo suporte | G26: 2 | H26: 4 | I26: 0 | J26: 2 | K26: 16.01.2026 | L26: 0.5625 | M26: 16.01.2026 | N26: 0.62916667 | O26: NDEL | P26: LIB PLAN | Q26: ZM01 | T26: 0 | W26: 0 | Y26: 0 | Z26: 0 | AB26: NÃO SE APLICA | AC26: 19
A27: 132714192 | B27: 2030740098 | C27: 230 | E27: CALDTU | F27: XV-62245_Remover suporte antigo | G27: 2 | H27: 4 | I27: 0 | J27: 2 | K27: 16.01.2026 | L27: 0.5625 | M27: 16.01.2026 | N27: 0.62916667 | O27: NDEL | P27: LIB PLAN | Q27: ZM01 | T27: 0 | W27: 0 | Y27: 0 | Z27: 0 | AB27: NÃO SE APLICA | AC27: 19
A28: 132175948 | B28: 2031067830 | C28: 30 | E28: CALDTU | F28: B-61101A Desconectar lhs sucção/descarga | G28: 2 | H28: 4 | I28: 0 | J28: 2 | K28: 12.01.2026 | L28: 0.3125 | M28: 12.01.2026 | N28: 0.39583333 | O28: NDEL | P28: LIB PLAN | Q28: ZM01 | T28: 0 | W28: 0 | Y28: 0 | Z28: 0 | AB28: NÃO SE APLICA | AC28: 19
A29: 132175955 | B29: 2031067830 | C29: 130 | E29: CALDTU | F29: B-61101A Flangear a cego sucção/descarga | G29: 2 | H29: 4 | I29: 0 | J29: 2 | K29: 13.01.2026 | L29: 0.4375 | M29: 13.01.2026 | N29: 0.5625 | O29: NDEL | P29: LIB PLAN | Q29: ZM01 | T29: 0 | W29: 0 | Y29: 0 | Z29: 0 | AB29: NÃO SE APLICA | AC29: 19
A30: 131922793 | B30: 2031080650 | C30: 10 | E30: CALDTU | F30: FT6205: subst. elem. filtrantes se neces | G30: 2 | H30: 12 | I30: 0 | J30: 6 | K30: 12.01.2026 | L30: 0.62083333 | M30: 13.01.2026 | N30: 0.45416667 | O30: NDEL EVCO | P30: LIB PLAN | Q30: ZM01 | T30: 0 | W30: 1 | X30: X | Y30: 0 | Z30: 0 | AC30: 19
A31: 132940829 | B31: 2031182582 | C31: 66 | E31: CALDTU | F31: PV-40154_PV-40154_Remov.cap/intal.mangue | G31: 2 | H31: 4 | I31: 0 | J31: 2 | K31: 13.01.2026 | L31: 0.37083333 | M31: 13.01.2026 | N31: 0.4375 | O31: NDEL | P31: LIB PLAN | Q31: ZM01 | T31: 0 | W31: 0 | Y31: 0 | Z31: 0 | AA31: 2 | AB31: NÃO SE APLICA | AC31: 19
A32: 132580092 | B32: 2031182582 | C32: 70 | E32: CALDTU | F32: PV-40154_Remover PV/flangear a cego | G32: 2 | H32: 4 | I32: 0 | J32: 2 | K32: 13.01.2026 | L32: 0.4375 | M32: 13.01.2026 | N32: 0.54583333 | O32: NDEL | P32: LIB PLAN | Q32: ZM01 | T32: 0 | W32: 0 | Y32: 0 | Z32: 0 | AA32: 2 | AB32: NÃO SE APLICA | AC32: 19
A33: 132685317 | B33: 2031202862 | C33: 20 | E33: CALDTU | F33: P-B-61101A-Remover Permutador | G33: 2 | H33: 6 | I33: 0 | J33: 3 | K33: 12.01.2026 | L33: 0.47916667 | M33: 12.01.2026 | N33: 0.62083333 | O33: NDEL | P33: LIB PLAN | Q33: ZM01 | T33: 0 | W33: 1 | X33: X | Y33: 0 | Z33: 0 | AC33: 19
A34: 132685324 | B34: 2031202862 | C34: 35 | E34: CALDTU | F34: P-B-61101A-Limpar Filtro | G34: 2 | H34: 2 | I34: 0 | J34: 1 | K34: 12.01.2026 | L34: 0.6875 | M34: 12.01.2026 | N34: 0.72083333 | O34: NDEL | P34: LIB PLAN | Q34: ZM01 | T34: 0 | W34: 1 | X34: X | Y34: 0 | Z34: 0 | AC34: 19
A35: 132685320 | B35: 2031202862 | C35: 50 | E35: CALDTU | F35: P-B-61101A-Realizar Teste Hidrostático | G35: 2 | H35: 8 | I35: 0 | J35: 4 | K35: 13.01.2026 | L35: 0.34583333 | M35: 13.01.2026 | N35: 0.47916667 | O35: NDEL | P35: LIB PLAN | Q35: ZM01 | T35: 0 | W35: 1 | X35: X | Y35: 0 | Z35: 0 | AC35: 19
A36: 132685321 | B36: 2031202862 | C36: 60 | E36: CALDTU | F36: P-B-61101A-Instalar Permutador | G36: 2 | H36: 6 | I36: 0 | J36: 3 | K36: 13.01.2026 | L36: 0.47916667 | M36: 13.01.2026 | N36: 0.62083333 | O36: NDEL | P36: LIB PLAN | Q36: ZM01 | T36: 0 | W36: 1 | X36: X | Y36: 0 | Z36: 0 | AC36: 19
A37: 133107751 | B37: 2031240660 | C37: 240 | E37: CALDTU | F37: P-6302B Rep Sede Ved Conf. Inspe Carrete | G37: 2 | H37: 16 | I37: 0 | J37: 8 | K37: 12.01.2026 | L37: 0 | M37: 12.01.2026 | N37: 0.33333333 | O37: NDEL | P37: LIB PLAN | Q37: ZM01 | T37: 0 | W37: 0 | Y37: 0 | Z37: 0 | AA37: 2 | AB37: NÃO SE APLICA | AC37: 19
A38: 134039678 | B38: 2031240660 | C38: 275 | E38: CALDTU | F38: P-6302B Adequar suporte no campo | G38: 2 | H38: 16 | I38: 0 | J38: 8 | K38: 12.01.2026 | L38: 0 | M38: 12.01.2026 | N38: 0.33333333 | O38: NDEL | P38: LIB PLAN | Q38: ZM01 | T38: 0 | W38: 0 | Y38: 0 | Z38: 0 | AA38: 2 | AB38: NÃO SE APLICA | AC38: 19
A39: 133107765 | B39: 2031240660 | C39: 360 | E39: CALDTU | F39: P-6302B Ap.usinagem/remover prisioneiro | G39: 2 | H39: 16 | I39: 0 | J39: 8 | K39: 12.01.2026 | L39: 0 | M39: 12.01.2026 | N39: 0.33333333 | O39: NDEL | P39: LIB PLAN | Q39: ZM01 | T39: 0 | W39: 0 | Y39: 0 | Z39: 0 | AA39: 2 | AB39: NÃO SE APLICA | AC39: 19
A40: 133107769 | B40: 2031240660 | C40: 400 | E40: CALDTU | F40: P-6302B Instalar prisioneiros | G40: 2 | H40: 12 | I40: 0 | J40: 6 | K40: 12.01.2026 | L40: 0 | M40: 12.01.2026 | N40: 0.25 | O40: NDEL | P40: LIB PLAN | Q40: ZM01 | T40: 0 | W40: 0 | Y40: 0 | Z40: 0 | AA40: 2 | AB40: NÃO SE APLICA | AC40: 19
...

Sheet MANDTU UT
H1: =SUM(H3:H1048576) -> 942
A2: Confirm | B2: Ordem | C2: Oper | D2: Subop | E2: CenTrabOp | F2: Txt. Breve operação | G2: executenta | H2: Trabalho | I2: TrbReal | J2: Duração
A3: 112410188 | B3: 2026756739 | C3: 6 | E3: MANDTU | F3: CH-4601_Montar acesso ao teto da CH | G3: 4 | H3: 16 | I3: 0 | J3: 4 | K3: 12.01.2026 | L3: 0.3125 | M3: 12.01.2026 | N3: 0.44583333 | O3: NDEL | P3: LIB PLAN | Q3: ZM01 | T3: 0 | W3: 0 | Y3: 0 | Z3: 0 | AA3: 2 | AC3: 19
A4: 107181770 | B4: 2026756739 | C4: 50 | E4: MANDTU | F4: CH-4601_Desmontar barraca de cobertura | G4: 4 | H4: 4 | I4: 0 | J4: 1 | K4: 16.01.2026 | L4: 0.42083333 | M4: 16.01.2026 | N4: 0.45416667 | O4: NDEL | P4: LIB PLAN | Q4: ZM01 | T4: 0 | W4: 0 | Y4: 0 | Z4: 0 | AA4: 2 | AC4: 19
A5: 112410189 | B5: 2026756739 | C5: 60 | E5: MANDTU | F5: CH-4601_Desmontar acesso ao teto da CH | G5: 4 | H5: 8 | I5: 0 | J5: 2 | K5: 16.01.2026 | L5: 0.45416667 | M5: 16.01.2026 | N5: 0.5625 | O5: NDEL | P5: LIB PLAN | Q5: ZM01 | T5: 0 | W5: 0 | Y5: 0 | Z5: 0 | AA5: 2 | AC5: 19
A6: 114052334 | B6: 2028265715 | C6: 120 | E6: MANDTU | F6: R-VE-6151H-Montar plataforma de acesso | G6: 8 | H6: 48 | I6: 13.1 | J6: 6 | K6: 12.01.2026 | L6: 0.5875 | M6: 12.01.2026 | N6: 0.72045139 | O6: NDEL CO01 | P6: CNPA LIB PLAN | Q6: ZM01 | T6: 0 | W6: 0 | Y6: 0 | Z6: 0 | AB6: NÃO SE APLICA | AC6: 19
A7: 134596247 | B7: 2028265715 | C7: 141 | E7: MANDTU | F7: R-VE-6151H M.A. e escoramemento da linha | G7: 4 | H7: 24 | I7: 0 | J7: 6 | K7: 13.01.2026 | L7: 0.38711806 | M7: 13.01.2026 | N7: 0.67878472 | O7: NDEL | P7: LIB PLAN | Q7: ZM01 | T7: 0 | W7: 0 | Y7: 0 | Z7: 0 | AB7: NÃO SE APLICA | AC7: 19
A8: 119630572 | B8: 2029164150 | C8: 110 | E8: MANDTU | F8: SE-610_M.andaime patio transformadores 3 | G8: 4 | H8: 20 | I8: 0 | J8: 5 | K8: 12.01.2026 | L8: 0.3125 | M8: 12.01.2026 | N8: 0.47916667 | O8: NDEL CO01 | P8: IMPR LIB PLAN | Q8: ZM01 | T8: 0 | W8: 0 | Y8: 0 | Z8: 0 | AA8: 1 | AC8: 19
A9: 119630574 | B9: 2029164150 | C9: 130 | E9: MANDTU | F9: SE-610_D.andaime patio transformadores 3 | G9: 4 | H9: 12 | I9: 0 | J9: 3 | K9: 13.01.2026 | L9: 0.45416667 | M9: 13.01.2026 | N9: 0.59583333 | O9: NDEL CO01 | P9: IMPR LIB PLAN | Q9: ZM01 | T9: 0 | W9: 0 | Y9: 0 | Z9: 0 | AA9: 1 | AC9: 19
A10: 125733769 | B10: 2029286067 | C10: 50 | E10: MANDTU | F10: HCV-22740_Montar bancada/pau de carga | G10: 4 | H10: 16 | I10: 0 | J10: 4 | K10: 12.01.2026 | L10: 0.3125 | M10: 12.01.2026 | N10: 0.47916667 | O10: NDEL CO01 | P10: LIB PLAN | Q10: ZM01 | T10: 0 | W10: 0 | Y10: 0 | Z10: 0 | AA10: 2 | AB10: NÃO SE APLICA | AC10: 19
A11: 129596780 | B11: 2029484416 | C11: 200 | E11: MANDTU | F11: $MAND_S-6302A:D.A Plataforma BV infer | G11: 4 | H11: 8 | I11: 0 | J11: 2 | K11: 12.01.2026 | L11: 0 | M11: 12.01.2026 | N11: 0.083333333 | O11: NDEL CO01 EVCO | P11: LIB PLAN | Q11: ZM01 | T11: 0 | W11: 0 | Y11: 0 | Z11: 0 | AA11: 2 | AB11: NÃO SE APLICA | AC11: 19
A12: 129596781 | B12: 2029484416 | C12: 210 | E12: MANDTU | F12: $MAND_S-6302A:D.A Acesso Raquet/BV | G12: 4 | H12: 16 | I12: 0 | J12: 4 | K12: 12.01.2026 | L12: 0 | M12: 12.01.2026 | N12: 0.16666667 | O12: NDEL CO01 EVCO | P12: LIB PLAN | Q12: ZM01 | T12: 0 | W12: 0 | Y12: 0 | Z12: 0 | AA12: 2 | AB12: NÃO SE APLICA | AC12: 19
A13: 121735286 | B13: 2029508737 | C13: 120 | E13: MANDTU | F13: PI-63556:Dand.após isolam.sul GV-6302 | G13: 4 | H13: 8 | I13: 0 | J13: 2 | K13: 12.01.2026 | L13: 0.47916667 | M13: 12.01.2026 | N13: 0.5875 | O13: NDEL CO01 | P13: LIB PLAN | Q13: ZM01 | T13: 0 | W13: 0 | Y13: 0 | Z13: 0 | AA13: 2 | AB13: NÃO SE APLICA | AC13: 19
A14: 130294144 | B14: 2029732592 | C14: 217 | E14: MANDTU | F14: U-631_D. torres de andaime Ponto 07 | G14: 8 | H14: 32 | I14: 0 | J14: 4 | K14: 12.01.2026 | L14: 0.72083333 | M14: 13.01.2026 | N14: 0.4375 | O14: NDEL | P14: IMPR LIB PLAN | Q14: ZM01 | T14: 0 | W14: 0 | Y14: 0 | Z14: 0 | AA14: 1 | AB14: NÃO SE APLICA | AC14: 19
A15: 130294145 | B15: 2029732592 | C15: 218 | E15: MANDTU | F15: U-631_Montar torres de andaime Ponto 08 | G15: 8 | H15: 64 | I15: 0 | J15: 8 | K15: 13.01.2026 | L15: 0.4375 | M15: 14.01.2026 | N15: 0.32916667 | O15: NDEL | P15: IMPR LIB PLAN | Q15: ZM01 | T15: 0 | W15: 0 | Y15: 0 | Z15: 0 | AA15: 1 | AB15: NÃO SE APLICA | AC15: 19
A16: 130294147 | B16: 2029732592 | C16: 220 | E16: MANDTU | F16: U-631_D. torres de andaime Ponto 08 | G16: 8 | H16: 32 | I16: 0 | J16: 4 | K16: 14.01.2026 | L16: 0.34583333 | M16: 14.01.2026 | N16: 0.47916667 | O16: NDEL | P16: IMPR LIB PLAN | Q16: ZM01 | T16: 0 | W16: 0 | Y16: 0 | Z16: 0 | AA16: 1 | AB16: NÃO SE APLICA | AC16: 19
A17: 130294148 | B17: 2029732592 | C17: 221 | E17: MANDTU | F17: U-631_Montar torres de andaime Ponto 09 | G17: 8 | H17: 64 | I17: 0 | J17: 8 | K17: 14.01.2026 | L17: 0.47916667 | M17: 15.01.2026 | N17: 0.37083333 | O17: NDEL | P17: IMPR LIB PLAN | Q17: ZM01 | T17: 0 | W17: 0 | Y17: 0 | Z17: 0 | AA17: 1 | AB17: NÃO SE APLICA | AC17: 19
A18: 130294150 | B18: 2029732592 | C18: 223 | E18: MANDTU | F18: U-631_D. torres de andaime Ponto 09 | G18: 8 | H18: 32 | I18: 0 | J18: 4 | K18: 15.01.2026 | L18: 0.3875 | M18: 15.01.2026 | N18: 0.5625 | O18: NDEL | P18: IMPR LIB PLAN | Q18: ZM01 | T18: 0 | W18: 0 | Y18: 0 | Z18: 0 | AA18: 1 | AB18: NÃO SE APLICA | AC18: 19
A19: 130294151 | B19: 2029732592 | C19: 224 | E19: MANDTU | F19: U-631_Montar torres de andaime Ponto 10 | G19: 8 | H19: 64 | I19: 0 | J19: 8 | K19: 15.01.2026 | L19: 0.5625 | M19: 16.01.2026 | N19: 0.4125 | O19: NDEL | P19: IMPR LIB PLAN | Q19: ZM01 | T19: 0 | W19: 0 | Y19: 0 | Z19: 0 | AA19: 1 | AB19: NÃO SE APLICA | AC19: 19
A20: 130294153 | B20: 2029732592 | C20: 226 | E20: MANDTU | F20: U-631_D. torres de andaime Ponto 10 | G20: 8 | H20: 32 | I20: 0 | J20: 4 | K20: 16.01.2026 | L20: 0.42916667 | M20: 16.01.2026 | N20: 0.60416667 | O20: NDEL | P20: IMPR LIB PLAN | Q20: ZM01 | T20: 0 | W20: 0 | Y20: 0 | Z20: 0 | AA20: 1 | AB20: NÃO SE APLICA | AC20: 19
A21: 130294154 | B21: 2029732592 | C21: 227 | E21: MANDTU | F21: U-631_Montar torres de andaime Ponto 11 | G21: 8 | H21: 64 | I21: 0 | J21: 8 | K21: 16.01.2026 | L21: 0.60416667 | M21: 19.01.2026 | N21: 0.49583333 | O21: NDEL | P21: IMPR LIB PLAN | Q21: ZM01 | T21: 0 | W21: 0 | Y21: 0 | Z21: 0 | AA21: 1 | AB21: NÃO SE APLICA | AC21: 19
A22: 125755039 | B22: 2029900061 | C22: 1040 | E22: MANDTU | F22: $MAND.V-6207:D.A. Para ME/Raquet/Abertu | G22: 4 | H22: 16 | I22: 0 | J22: 4 | K22: 12.01.2026 | L22: 0 | M22: 12.01.2026 | N22: 0.16666667 | O22: NDEL CO01 | P22: IMPR LIB PLAN | Q22: ZM01 | T22: 0 | W22: 0 | Y22: 0 | Z22: 0 | AC22: 19
A23: 125099353 | B23: 2030079558 | C23: 10 | E23: MANDTU | F23: B-6121E_Montar plataforma e pau-de-carga | G23: 4 | H23: 16 | I23: 0 | J23: 4 | K23: 16.01.2026 | L23: 0.3125 | M23: 16.01.2026 | N23: 0.44583333 | O23: NDEL CO01 | P23: LIB PLAN | Q23: ZM01 | T23: 0 | W23: 1 | X23: X | Y23: 0 | Z23: 0 | AC23: 19
A24: 125099356 | B24: 2030079558 | C24: 30 | E24: MANDTU | F24: B-6121E_Desmontar plataf. e pau-de-carga | G24: 4 | H24: 12 | I24: 0 | J24: 3 | K24: 16.01.2026 | L24: 0.6375 | M24: 19.01.2026 | N24: 0.3625 | O24: NDEL CO01 | P24: LIB PLAN | Q24: ZM01 | T24: 0 | W24: 1 | Y24: 0 | Z24: 0 | AC24: 19
A25: 126099599 | B25: 2030210738 | C25: 10 | E25: MANDTU | F25: U-620_Montar T. andaime ponto 10 | G25: 4 | H25: 16 | I25: 0 | J25: 4 | K25: 14.01.2026 | L25: 0.42083333 | M25: 14.01.2026 | N25: 0.59583333 | O25: NDEL CO01 | P25: LIB PLAN | Q25: ZM01 | T25: 0 | W25: 0 | Y25: 0 | Z25: 0 | AB25: NÃO SE APLICA | AC25: 19
A26: 127122542 | B26: 2030377954 | C26: 390 | E26: MANDTU | F26: TQ-6216:Desmontar andaimes linha de PAC | G26: 4 | H26: 32 | I26: 0 | J26: 8 | K26: 12.01.2026 | L26: 0 | M26: 12.01.2026 | N26: 0.33333333 | O26: NDEL CO01 EVCO | P26: LIB PLAN | Q26: ZM01 | T26: 0 | W26: 0 | Y26: 0 | Z26: 0 | AB26: NÃO SE APLICA | AC26: 19
A27: 130878506 | B27: 2030822754 | C27: 50 | E27: MANDTU | F27: TR-6121H- Montar andaime de acesso lest | G27: 4 | H27: 8 | I27: 0 | J27: 2 | K27: 13.01.2026 | L27: 0.42083333 | M27: 13.01.2026 | N27: 0.4875 | O27: NDEL CO01 EVCO | P27: LIB PLAN | Q27: ZM01 | T27: 0 | W27: 0 | Y27: 0 | Z27: 0 | AC27: 19
A28: 130878511 | B28: 2030822754 | C28: 65 | E28: MANDTU | F28: TR-6121H- D.A andaime de acesso lest | G28: 4 | H28: 4 | I28: 0 | J28: 1 | K28: 14.01.2026 | L28: 0.32083333 | M28: 14.01.2026 | N28: 0.35416667 | O28: NDEL CO01 | P28: LIB PLAN | Q28: ZM01 | T28: 0 | W28: 0 | Y28: 0 | Z28: 0 | AC28: 19
A29: 130878509 | B29: 2030822754 | C29: 80 | E29: MANDTU | F29: TR-6121H- Montar andaime de acesso oest | G29: 4 | H29: 4 | I29: 0 | J29: 1 | K29: 14.01.2026 | L29: 0.3875 | M29: 14.01.2026 | N29: 0.42083333 | O29: NDEL CO01 | P29: LIB PLAN | Q29: ZM01 | T29: 0 | W29: 0 | Y29: 0 | Z29: 0 | AC29: 19
A30: 130878512 | B30: 2030822754 | C30: 100 | E30: MANDTU | F30: TR-6121H- D.A andaime de acesso oest | G30: 4 | H30: 4 | I30: 0 | J30: 1 | K30: 14.01.2026 | L30: 0.4875 | M30: 14.01.2026 | N30: 0.5625 | O30: NDEL CO01 | P30: LIB PLAN | Q30: ZM01 | T30: 0 | W30: 0 | Y30: 0 | Z30: 0 | AC30: 19
A31: 130487023 | B31: 2030910958 | C31: 50 | E31: MANDTU | F31: LSH-22062_Desmontar andaime | G31: 4 | H31: 8 | I31: 0 | J31: 2 | K31: 12.01.2026 | L31: 0.37916667 | M31: 12.01.2026 | N31: 0.44583333 | O31: NDEL | P31: LIB PLAN | Q31: ZM01 | T31: 0 | W31: 0 | Y31: 0 | Z31: 0 | AA31: 1 | AB31: NÃO SE APLICA | AC31: 19
A32: 130715419 | B32: 2030944321 | C32: 80 | E32: MANDTU | F32: XV-23408_Desmontar bancada andaime | G32: 4 | H32: 8 | I32: 0 | J32: 2 | K32: 12.01.2026 | L32: 0.4125 | M32: 12.01.2026 | N32: 0.47916667 | O32: NDEL | P32: LIB PLAN | Q32: ZM01 | T32: 0 | W32: 0 | Y32: 0 | Z32: 0 | AA32: 1 | AB32: NÃO SE APLICA | AC32: 19
A33: 132115133 | B33: 2031111332 | C33: 10 | E33: MANDTU | F33: $MAND-FT-6201E:Ap.and p/manutenção placa | G33: 4 | H33: 16 | I33: 0 | J33: 4 | K33: 15.01.2026 | L33: 0.4125 | M33: 15.01.2026 | N33: 0.5875 | O33: NDEL CO01 | P33: LIB PLAN | Q33: ZM01 | T33: 0 | W33: 0 | Y33: 0 | Z33: 0 | AB33: NÃO SE APLICA | AC33: 19
A34: 132684476 | B34: 2031202781 | C34: 10 | E34: MANDTU | F34: SF-22506C M.A. de acesso ao ramonador | G34: 4 | H34: 16 | I34: 0 | J34: 4 | K34: 14.01.2026 | L34: 0.5625 | M34: 14.01.2026 | N34: 0.69583333 | O34: NDEL | P34: LIB PLAN | Q34: ZM01 | T34: 0 | W34: 0 | Y34: 0 | Z34: 0 | AA34: 2 | AB34: NÃO SE APLICA | AC34: 19
A35: 133267902 | B35: 2031202781 | C35: 65 | D35: 30 | E35: MANDTU | F35: SF-22506C Descer materiais PS | G35: 2 | H35: 8 | I35: 0 | J35: 4 | K35: 16.01.2026 | L35: 0.4125 | M35: 16.01.2026 | N35: 0.5875 | O35: NDEL | P35: LIB PLAN | Q35: ZM01 | T35: 0 | W35: 0 | Y35: 0 | Z35: 0 | AA35: 2 | AB35: NÃO SE APLICA | AC35: 19
A36: 132917266 | B36: 2031202781 | C36: 60 | E36: MANDTU | F36: SF-22506C D.A. de acesso ao ramonador | G36: 4 | H36: 8 | I36: 0 | J36: 2 | K36: 16.01.2026 | L36: 0.34583333 | M36: 16.01.2026 | N36: 0.4125 | O36: NDEL | P36: LIB PLAN | Q36: ZM01 | T36: 0 | W36: 0 | Y36: 0 | Z36: 0 | AA36: 2 | AB36: NÃO SE APLICA | AC36: 19
A37: 132685325 | B37: 2031202862 | C37: 5 | E37: MANDTU | F37: P-B-61101A-M.A. plataforma acesso | G37: 4 | H37: 12 | I37: 0 | J37: 3 | K37: 12.01.2026 | L37: 0.3125 | M37: 12.01.2026 | N37: 0.4125 | O37: NDEL CO01 | P37: LIB PLAN | Q37: ZM01 | T37: 0 | W37: 1 | Y37: 0 | Z37: 0 | AC37: 19
A38: 132685326 | B38: 2031202862 | C38: 90 | E38: MANDTU | F38: P-B-61101A-D.A. após manutenção | G38: 4 | H38: 6 | I38: 0 | J38: 1.5 | K38: 13.01.2026 | L38: 0.6875 | M38: 14.01.2026 | N38: 0.32083333 | O38: NDEL CO01 | P38: LIB PLAN | Q38: ZM01 | T38: 0 | W38: 1 | Y38: 0 | Z38: 0 | AC38: 19
A39: 133107766 | B39: 2031240660 | C39: 370 | E39: MANDTU | F39: $P-6302B M.A. Travar Painel Elétrico | G39: 4 | H39: 8 | I39: 0 | J39: 2 | K39: 12.01.2026 | L39: 0 | M39: 12.01.2026 | N39: 0.083333333 | O39: NDEL CO01 | P39: LIB PLAN | Q39: ZM01 | T39: 0 | W39: 0 | Y39: 0 | Z39: 0 | AA39: 2 | AB39: NÃO SE APLICA | AC39: 19
A40: 133107779 | B40: 2031240660 | C40: 500 | E40: MANDTU | F40: $P-6302B Apoio and.manut.permutador | G40: 4 | H40: 32 | I40: 0 | J40: 8 | K40: 12.01.2026 | L40: 0 | M40: 12.01.2026 | N40: 0.33333333 | O40: NDEL CO01 | P40: LIB PLAN | Q40: ZM01 | T40: 0 | W40: 0 | Y40: 0 | Z40: 0 | AA40: 2 | AB40: NÃO SE APLICA | AC40: 19
...

Sheet ORG
